Workbook

Sheet TOCs
D1: TABLE OF CONTENTS
B4: ITEM | I4: PAGE
A6: 1 | B6: Mutation form……………………………………………. | I6: 1
A7: 2 | B7: Plane page…………………………………………………........ | I7: 2
A8: 3 | B8: Table of contents…………………………………………………. | I8: 3
A9: 4 | B9: Job History………………………………………………………. | I9: 4
A10: 5 | B10: Index to computations…………………………………………….. | I10: 5
A11: 6 | B11: Abstract of coordinates …………………………..……………… | I11: 6
A12: 7 | B12: Datum Coordinates and Computations…………………………… | I12: 8
A13: 8 | B13: Index diagram……………………………………………………. | I13: 9
A14: 9 | B14: Field sheets………………………………………………………. | I14: 10
A15: 10 | B15: Traverse Computation sheet………………………………............ | I15: 19
A16: 11 | B16: Area Computation……….……………………………………….. | I16: 21

Sheet Job History

Sheet INDEX
B3: INDEX TO COMPUTATION
B6: Using a RTK GPS a second class traverse
B7: was carried out with the following corrections:
B10: U T M Scale factor -0.3737 | G10: 0.4531
B12: M S L -0.1911 | G12: -0.215
B14: C. C. -0.5648 | F14: =G10+G12 -> 0.2381
C17: M F = | D17: =1+F14/1000 -> 1.0002381
B24: Note: | C24: All the other corrections were automatically done by the GPS and so the
C25: recorded distance is the horizontal distance.
G29: INDEX TO COMPUTATIONS
E32: The job was done using the total station TC 1600 observing horizontal distances.
E33: The following are the standard corrections per 1000 which were applied to obtain
E34: the final distances.
E36: Height above sea level | H36: = | I36: 1220 | J36: (WAKISO)
E38: Mean sea level correction | H38: = | I38: -0.1911
E40: Scale factor | H40: = | I40: -0.3737
E42: Combined correction | H42: = | I42: =I38+I40 -> -0.5648
E44: Multiplication Factor MF | H44: = | I44: =(1+I42/1000) -> 0.9994352
E46: Note:
E47: All the other corrections were made automatically done by the total station and so the
E48: the recorded distances are truly horizontal.
L56: INDEX TO COMPUTATIONS
J59: The job was done using the total station TC 1600 observing horizontal distances.
J60: The following are the standard corrections per 1000 which were applied to obtain
J61: the final distances.
J63: Height above sea level | M63: = | N63: 1220 | O63: (WAKISO)
J65: Mean sea level correction | M65: = | N65: -0.1911
J67: Scale factor | M67: = | N67: -0.3737
J69: Combined correction | M69: = | N69: =N65+N67 -> -0.5648
J71: Multiplication Factor MF | M71: = | N71: =(1+N69/1000) -> 0.9994352
J73: Note:
J74: All the other corrections were made automatically done by the total station and so the
J75: the recorded distances are truly horizontal.
D80: INDEX TO COMPUTATIONS
B83: The job was done using the total station ……….. observing horizontal distances.
B84: The following are the standard corrections which were applied to obtain to
B85: the final distances.
B87: Height above sea level | E87: = | F87: 1220 | G87: (District)
B89: Mean sea level correction | E89: = | F89: -0.1911
B91: Scale factor | E91: = | F91: -0.3737
...

Sheet ABSTRACT
D3: ABSTRACT OF RESULTS
D4: Stn | E4: Northings | G4: Eastings
D5: CM1 | E5: 45895.954 | G5: 210949.51
D6: CM2 | E6: 45877.618 | G6: 210925.21
D7: CM3 | E7: 45870.529 | G7: 210920.11
D8: CM4 | E8: 45832.709 | G8: 210947.25
D9: CM5 | E9: 45825.057 | G9: 210953.83
D10: CM6 | E10: 45815.564 | G10: 210942.53
D11: CM7 | E11: 45799.001 | G11: 210933.99
D12: CL1 | E12: 45785.763 | G12: 210921.62
D13: CM8 | E13: 45790.378 | G13: 210928.68
D14: CM9 | E14: 45805.107 | G14: 210910.33
D15: CM10 | E15: 45794.092 | G15: 210899.83
D16: CM11 | E16: 45788.358 | G16: 210887.16
... D71: CM65 | E71: 45946.528 | G71: 210919.64

Sheet DTM
A1: DATUM COORDINATES AND COMPUTATIONS
A2: Stn | B2: Northings | C2: Eastings
A4: cm1 | B4: 46203.9 | C4: 210775.64 | D4: I/s No.
A5: DD/6126 | B5: 46145.06 | C5: 210808.14 | D5: I/s No.
A6: DD/6124 | B6: 46098.37 | C6: 210744.47 | D6: I/s No.
A7: cm2 | B7: 46162.99 | C7: 210703.93 | D7: I/s No.
A8: DD/6126 | B8: 46145.06 | C8: 210808.14 | D8: I/s No.
A9: cm1 | B9: 46203.9 | C9: 210775.64 | D9: I/s No.
B11: OPENING
A12: =A4 -> cm1 | B12: =B4 -> 46203.900 | C12: =C4 -> 210775.640 | D12: ±ΔN | E12: ±ΔE | H12: BEARING | K12: DIST
A13: =A6 -> DD/6124 | B13: =B6 -> 46098.370 | C13: =C6 -> 210744.470 | D13: =B12-B13 -> 105.530 | E13: =C12-C13 -> 31.170 | F13: =ATAN2(D13,E13)*180/PI() -> 16.45536172 | G13: =IF(F13<0,F13+360,F13) -> 16.45536172 | H13: =TRUNC(G13,0) -> 16 | I13: =TRUNC((G13-H13)*60,0) -> 27 | J13: =ROUND((G13-H13-I13/60)*3600,0) -> 19 | K13: =SQRT(D13^2+E13^2) -> 110.037
A15: =A5 -> DD/6126 | B15: =B5 -> 46145.060 | C15: =C5 -> 210808.140
A16: =A13 -> DD/6124 | B16: =B13 -> 46098.370 | C16: =C13 -> 210744.470 | D16: =B15-B16 -> 46.690 | E16: =C15-C16 -> 63.670 | F16: =ATAN2(D16,E16)*180/PI() -> 53.74694252 | G16: =IF(F16<0,F16+360,F16) -> 53.74694252 | H16: =TRUNC(G16,0) -> 53 | I16: =TRUNC((G16-H16)*60,0) -> 44 | J16: =ROUND((G16-H16-I16/60)*3600,0) -> 49 | K16: =SQRT(D16^2+E16^2) -> 78.955
B19: CLOSING
A20: =A8 -> DD/6126 | B20: =B8 -> 46145.060 | C20: =C8 -> 210808.140 | D20: =D12 -> ±ΔN | E20: =E12 -> ±ΔE | H20: BEARING
A21: =A7 -> cm2 | B21: =B7 -> 46162.990 | C21: =C7 -> 210703.930 | D21: =B20-B21 -> -17.930 | E21: =C20-C21 -> 104.210 | F21: =ATAN2(D21,E21)*180/PI() -> 99.76252123 | G21: =IF(F21<0,F21+360,F21) -> 99.76252123 | H21: =TRUNC(G21,0) -> 99 | I21: =TRUNC((G21-H21)*60,0) -> 45 | J21: =ROUND((G21-H21-I21/60)*3600,0) -> 45 | K21: =SQRT(D21^2+E21^2) -> 105.741
A23: =A9 -> cm1 | B23: =B9 -> 46203.900 | C23: =C9 -> 210775.640
A24: =A21 -> cm2 | B24: =B21 -> 46162.990 | C24: =C21 -> 210703.930 | D24: =B23-B24 -> 40.910 | E24: =C23-C24 -> 71.710 | F24: =ATAN2(D24,E24)*180/PI() -> 60.29557635 | G24: =IF(F24<0,F24+360,F24) -> 60.29557635 | H24: =TRUNC(G24,0) -> 60 | I24: =TRUNC((G24-H24)*60,0) -> 17 | J24: =ROUND((G24-H24-I24/60)*3600,0) -> 44 | K24: =SQRT(D24^2+E24^2) -> 82.559

Sheet Field notes
A1: Stn | B1: Observed | G1: Corr | I1: Direction | M1: Final Dist | N1: Stn | O1: Meas Dist
A5: FIELD NOTES
M6: =INDEX!F95 -> 0.9994352
A7: Stn | B7: Observed | G7: Corr | I7: Direction | M7: Final Dist | N7: Stn | O7: Meas Dist
K8: AT | L8: =TRVS!A11 -> DD/6124
A9: =DTM!A12 -> cm1 | B9: =TRUNC(F9,0) -> 16 | C9: =TRUNC((F9-B9)*60,0) -> 27 | D9: =ROUND(((F9-B9)-C9/60)*3600,0) -> 19 | E9: =F9 -> 16 | F9: =I9+J9/60+K9/3600-H9/3600 -> 16 | H9: 0 | I9: =TRVS!B9 -> 16 | J9: =TRVS!C9 -> 27 | K9: =TRVS!D9 -> 19
B10: =TRUNC(F10,0) -> 196 | C10: =TRUNC((F10-B10)*60,0) -> 27 | D10: =ROUND(((F10-B10)-C10/60)*3600,0) -> 18 | E10: =E9-(B11+C11/60+D11/3600) -> -164 | F10: =IF(E10>0,E10,E10+360) -> 196
B11: 180 | C11: 0 | D11: 1
A13: =DTM!A15 -> DD/6126 | B13: =TRUNC(F13,0) -> 53 | C13: =TRUNC((F13-B13)*60,0) -> 44 | D13: =ROUND(((F13-B13)-C13/60)*3600,0) -> 49 | E13: =F13 -> 54 | F13: =I13+J13/60+K13/3600-(H13+G13)/3600 -> 54 | G13: =ROUND(((B11+C11/60+D11/3600)-(B15+C15/60+D15/3600))/2*3600,0) -> 0 | H13: 0 | I13: =TRVS!B10 -> 53 | J13: =TRVS!C10 -> 44 | K13: =TRVS!D10 -> 49
B14: =TRUNC(F14,0) -> 233 | C14: =TRUNC((F14-B14)*60,0) -> 44 | D14: =ROUND(((F14-B14)-C14/60)*3600,0) -> 48 | E14: =E13-(B15+C15/60+D15/3600) -> -126 | F14: =IF(E14>0,E14,E14+360) -> 234
B15: 180 | C15: 0 | D15: 1
A17: =TRVS!A12 -> CM1 | B17: =TRUNC(F17,0) -> 134 | C17: =TRUNC((F17-B17)*60,0) -> 37 | D17: =ROUND(((F17-B17)-C17/60)*3600,0) -> 57 | E17: =F17 -> 135 | F17: =I17+J17/60+K17/3600-(H17+G17)/3600 -> 135 | G17: =ROUND(((B11+C11/60+D11/3600)-(B19+C19/60+D19/3600))/2*3600,0) -> 3 | H17: =H9 -> 0 | I17: =TRVS!B12 -> 134 | J17: =TRVS!C12 -> 37 | K17: =TRVS!D12 -> 60 | L17: =L8 -> DD/6124 | M17: =TRVS!L12 -> 288.119 | N17: =A17 -> CM1 | O17: =M17/$M$6 -> 288.282
B18: =TRUNC(F18,0) -> 314 | C18: =TRUNC((F18-B18)*60,0) -> 38 | D18: =ROUND(((F18-B18)-C18/60)*3600,0) -> 2 | E18: =E17-(B19+C19/60+D19/3600) -> -45 | F18: =IF(E18>0,E18,E18+360) -> 315
B19: 179 | C19: 59 | D19: 55
K20: AT | L20: =A17 -> CM1
A21: =L8 -> DD/6124 | B21: =TRUNC(F21,0) -> 314 | C21: =TRUNC((F21-B21)*60,0) -> 37 | D21: =ROUND(((F21-B21)-C21/60)*3600,0) -> 57 | E21: =F21 -> 315 | F21: =I21+J21/60+K21/3600-(H21+G21)/3600 -> 315 | H21: 3 | I21: =IF(I17<180,I17+180,I17-180) -> 314 | J21: =J17 -> 37 | K21: =K17 -> 60
B22: =TRUNC(F22,0) -> 114 | C22: =TRUNC((F22-B22)*60,0) -> 37 | D22: =ROUND(((F22-B22)-C22/60)*3600,0) -> 56 | E22: =E21-(B23+C23/60+D23/3600) -> 115 | F22: =IF(E22>0,E22,E22+360) -> 115
B23: 200 | C23: 0 | D23: 1
A25: =TRVS!A13 -> CM2 | B25: =TRUNC(F25,0) -> 232 | C25: =TRUNC((F25-B25)*60,0) -> 58 | D25: =ROUND(((F25-B25)-C25/60)*3600,0) -> 14 | E25: =F25 -> 233 | F25: =I25+J25/60+K25/3600-(H25+G25)/3600 -> 233 | G25: =ROUND(((B23+C23/60+D23/3600)-(B27+C27/60+D27/3600))/2*3600,0) -> -1 | H25: =H21 -> 3 | I25: =TRVS!B13 -> 232 | J25: =TRVS!C13 -> 58 | K25: =TRVS!D13 -> 16 | L25: =L20 -> CM1 | M25: =TRVS!L13 -> 30.450 | N25: =A25 -> CM2 | O25: =M25/$M$6 -> 30.467
B26: =TRUNC(F26,0) -> 32 | C26: =TRUNC((F26-B26)*60,0) -> 58 | D26: =ROUND(((F26-B26)-C26/60)*3600,0) -> 12 | E26: =E25-(B27+C27/60+D27/3600) -> 33 | F26: =IF(E26>0,E26,E26+360) -> 33
B27: 200 | C27: 0 | D27: 2
K28: AT | L28: =A25 -> CM2
A29: =L20 -> CM1 | B29: =TRUNC(F29,0) -> 52 | C29: =TRUNC((F29-B29)*60,0) -> 58 | D29: =ROUND(((F29-B29)-C29/60)*3600,0) -> 15 | E29: =F29 -> 53 | F29: =I29+J29/60+K29/3600-(H29+G29)/3600 -> 53 | H29: 1 | I29: =IF(I25<180,I25+180,I25-180) -> 52 | J29: =J25 -> 58 | K29: =K25 -> 16
B30: =TRUNC(F30,0) -> 232 | C30: =TRUNC((F30-B30)*60,0) -> 58 | D30: =ROUND(((F30-B30)-C30/60)*3600,0) -> 14 | E30: =E29-(B31+C31/60+D31/3600) -> -127 | F30: =IF(E30>0,E30,E30+360) -> 233
B31: 180 | C31: 0 | D31: 1
A33: =TRVS!A14 -> CM3 | B33: =TRUNC(F33,0) -> 215 | C33: =TRUNC((F33-B33)*60,0) -> 42 | D33: =ROUND(((F33-B33)-C33/60)*3600,0) -> 57 | E33: =F33 -> 216 | F33: =I33+J33/60+K33/3600-(H33+G33)/3600 -> 216 | G33: =ROUND(((B31+C31/60+D31/3600)-(B35+C35/60+D35/3600))/2*3600,0) -> -3 | H33: =H29 -> 1 | I33: =TRVS!B14 -> 215 | J33: =TRVS!C14 -> 42 | K33: =TRVS!D14 -> 55 | L33: =L28 -> CM2 | M33: =TRVS!L14 -> 8.731 | N33: =A33 -> CM3 | O33: =M33/$M$6 -> 8.736
B34: =TRUNC(F34,0) -> 35 | C34: =TRUNC((F34-B34)*60,0) -> 42 | D34: =ROUND(((F34-B34)-C34/60)*3600,0) -> 50 | E34: =E33-(B35+C35/60+D35/3600) -> 36 | F34: =IF(E34>0,E34,E34+360) -> 36
B35: 180 | C35: 0 | D35: 7
K36: AT | L36: =A33 -> CM3
A37: =L28 -> CM2 | B37: =TRUNC(F37,0) -> 35 | C37: =TRUNC((F37-B37)*60,0) -> 42 | D37: =ROUND(((F37-B37)-C37/60)*3600,0) -> 56 | E37: =F37 -> 36 | F37: =I37+J37/60+K37/3600-(H37+G37)/3600 -> 36 | H37: -1 | I37: =IF(I33<180,I33+180,I33-180) -> 35 | J37: =J33 -> 42 | K37: =K33 -> 55
B38: =TRUNC(F38,0) -> 215 | C38: =TRUNC((F38-B38)*60,0) -> 42 | D38: =ROUND(((F38-B38)-C38/60)*3600,0) -> 54 | E38: =E37-(B39+C39/60+D39/3600) -> -144 | F38: =IF(E38>0,E38,E38+360) -> 216
B39: 180 | C39: 0 | D39: 2
A41: =TRVS!A15 -> CM4 | B41: =TRUNC(F41,0) -> 144 | C41: =TRUNC((F41-B41)*60,0) -> 20 | D41: =ROUND(((F41-B41)-C41/60)*3600,0) -> 9 | E41: =F41 -> 144 | F41: =I41+J41/60+K41/3600-(H41+G41)/3600 -> 144 | G41: =ROUND(((B39+C39/60+D39/3600)-(B43+C43/60+D43/3600))/2*3600,0) -> 2 | H41: =H37 -> -1 | I41: =TRVS!B15 -> 144 | J41: =TRVS!C15 -> 20 | K41: =TRVS!D15 -> 10 | L41: =L36 -> CM3 | M41: =TRVS!L15 -> 46.551 | N41: =A41 -> CM4 | O41: =M41/$M$6 -> 46.577
B42: =TRUNC(F42,0) -> 324 | C42: =TRUNC((F42-B42)*60,0) -> 20 | D42: =ROUND(((F42-B42)-C42/60)*3600,0) -> 11 | E42: =E41-(B43+C43/60+D43/3600) -> -36 | F42: =IF(E42>0,E42,E42+360) -> 324
B43: 179 | C43: 59 | D43: 58
K44: AT | L44: =A41 -> CM4
A45: =L36 -> CM3 | B45: =TRUNC(F45,0) -> 324 | C45: =TRUNC((F45-B45)*60,0) -> 20 | D45: =ROUND(((F45-B45)-C45/60)*3600,0) -> 11 | E45: =F45 -> 324 | F45: =I45+J45/60+K45/3600-(H45+G45)/3600 -> 324 | H45: -1 | I45: =IF(I41<180,I41+180,I41-180) -> 324 | J45: =J41 -> 20 | K45: =K41 -> 10
B46: =TRUNC(F46,0) -> 144 | C46: =TRUNC((F46-B46)*60,0) -> 20 | D46: =ROUND(((F46-B46)-C46/60)*3600,0) -> 10 | E46: =E45-(B47+C47/60+D47/3600) -> 144 | F46: =IF(E46>0,E46,E46+360) -> 144
B47: 180 | C47: 0 | D47: 1
A49: =TRVS!A16 -> CM5 | B49: =TRUNC(F49,0) -> 139 | C49: =TRUNC((F49-B49)*60,0) -> 18 | D49: =ROUND(((F49-B49)-C49/60)*3600,0) -> 6 | E49: =F49 -> 139 | F49: =I49+J49/60+K49/3600-(H49+G49)/3600 -> 139 | G49: =ROUND(((B47+C47/60+D47/3600)-(B51+C51/60+D51/3600))/2*3600,0) -> 1 | H49: =H45 -> -1 | I49: =TRVS!B16 -> 139 | J49: =TRVS!C16 -> 18 | K49: =TRVS!D16 -> 6 | L49: =L44 -> CM4 | M49: =TRVS!L16 -> 10.093 | N49: =A49 -> CM5 | O49: =M49/$M$6 -> 10.098
...

Sheet TRVS
A1: Stn | B1: Direction | E1: Corr | G1: Bearing | L1: Distance | N1: ±ΔN/m | P1: Corr | Q1: ±ΔE/m | R1: Corr | S1: Stn | T1: N/m | U1: E/m | V1: Remarks
D5: TRAVERSE COMPUTATION SHEET
A6: PROJECT -------------------------------------------------------------------Page---------------of-------------------------------------
A7: Date-----------------------------------------Observed By-----------------------------Compiled By------------------------------
A8: Stn | B8: Direction | E8: Corr | G8: Bearing | L8: Distance | N8: ±ΔN/m | O8: xx | P8: Corr | Q8: ±ΔE/m | R8: Corr | S8: Stn | T8: N/m | U8: E/m | V8: Remarks
A9: =DTM!A12 -> cm1 | B9: =TRUNC(F9,0) -> 16 | C9: =TRUNC((F9-B9)*60,0) -> 27 | D9: =ROUND((F9-B9-C9/60)*3600,0) -> 19 | E9: 0 | F9: =G9+H9/60+I9/3600-E9/3600 -> 16 | G9: =DTM!H13 -> 16 | H9: =DTM!I13 -> 27 | I9: =DTM!J13 -> 19 | S9: =A9 -> cm1 | V9: =DTM!D4 -> I/s No.
A10: =DTM!A15 -> DD/6126 | B10: =TRUNC(F10,0) -> 53 | C10: =TRUNC((F10-B10)*60,0) -> 44 | D10: =ROUND((F10-B10-C10/60)*3600,0) -> 49 | E10: 0 | F10: =G10+H10/60+I10/3600-E10/3600 -> 54 | G10: =DTM!H16 -> 53 | H10: =DTM!I16 -> 44 | I10: =DTM!J16 -> 49 | S10: =A10 -> DD/6126 | V10: =DTM!D5 -> I/s No.
A11: =S11 -> DD/6124 | E11: =AVERAGE(E9:E10) -> 0 | O11: ee | S11: =DTM!A13 -> DD/6124 | T11: =DTM!B13 -> 46098.370 | U11: =DTM!C13 -> 210744.470 | V11: =DTM!D6 -> I/s No.
A12: =S12 -> CM1 | B12: =TRUNC(F12,0) -> 134 | C12: =TRUNC((F12-B12)*60,0) -> 37 | D12: =ROUND((F12-B12-C12/60)*3600,0) -> 60 | E12: =E84 -> 1 | F12: =G12+H12/60+I12/3600-E12/3600 -> 135 | G12: =TRUNC(J12,0) -> 134 | H12: =TRUNC((J12-G12)*60,0) -> 38 | I12: =ROUND(((J12-G12)-H12/60)*3600,0) -> 1 | J12: =IF(K12<0,K12+360,K12) -> 135 | K12: =ATAN2(N12,Q12)/PI()*180 -> 135 | L12: =ROUND((SQRT(N12^2+Q12^2)),5) -> 288.119 | M12: =SQRT((T12-T11)^2+(U12-U11)^2) -> 288.123 | N12: =T12-T11-P12 -> -202.424 | O12: 288.12157 | P12: =ROUND(($T$82*$O12/$O$80),3) -> 0.008 | Q12: =U12-U11-R12 -> 205.030 | R12: =ROUND(($U$82*$O12/$O$80),3) -> 0.013 | S12: CM1 | T12: 45895.954 | U12: 210949.51
A13: =S13 -> CM2 | B13: =TRUNC(F13,0) -> 232 | C13: =TRUNC((F13-B13)*60,0) -> 58 | D13: =ROUND((F13-B13-C13/60)*3600,0) -> 16 | E13: =E12+E$84 -> 2 | F13: =G13+H13/60+I13/3600-E13/3600 -> 233 | G13: =TRUNC(J13,0) -> 232 | H13: =TRUNC((J13-G13)*60,0) -> 58 | I13: =ROUND(((J13-G13)-H13/60)*3600,0) -> 18 | J13: =IF(K13<0,K13+360,K13) -> 233 | K13: =ATAN2(N13,Q13)/PI()*180 -> -127 | L13: =ROUND((SQRT(N13^2+Q13^2)),5) -> 30.450 | M13: =SQRT((T13-T12)^2+(U13-U12)^2) -> 30.448 | N13: =T13-T12-P13 -> -18.337 | O13: 30.45531 | P13: =ROUND(($T$82*$O13/$O$80),3) -> 0.001 | Q13: =U13-U12-R13 -> -24.309 | R13: =ROUND(($U$82*$O13/$O$80),3) -> 0.001 | S13: CM2 | T13: 45877.618 | U13: 210925.21
A14: =S14 -> CM3 | B14: =TRUNC(F14,0) -> 215 | C14: =TRUNC((F14-B14)*60,0) -> 42 | D14: =ROUND((F14-B14-C14/60)*3600,0) -> 55 | E14: =E13+E$84 -> 3 | F14: =G14+H14/60+I14/3600-E14/3600 -> 216 | G14: =TRUNC(J14,0) -> 215 | H14: =TRUNC((J14-G14)*60,0) -> 42 | I14: =ROUND(((J14-G14)-H14/60)*3600,0) -> 58 | J14: =IF(K14<0,K14+360,K14) -> 216 | K14: =ATAN2(N14,Q14)/PI()*180 -> -144 | L14: =ROUND((SQRT(N14^2+Q14^2)),5) -> 8.731 | M14: =SQRT((T14-T13)^2+(U14-U13)^2) -> 8.731 | N14: =T14-T13-P14 -> -7.089 | O14: 8.73396 | P14: =ROUND(($T$82*$O14/$O$80),3) -> 0.000 | Q14: =U14-U13-R14 -> -5.097 | R14: =ROUND(($U$82*$O14/$O$80),3) -> 0.000 | S14: CM3 | T14: 45870.529 | U14: 210920.11
A15: =S15 -> CM4 | B15: =TRUNC(F15,0) -> 144 | C15: =TRUNC((F15-B15)*60,0) -> 20 | D15: =ROUND((F15-B15-C15/60)*3600,0) -> 10 | E15: =E14+E$84 -> 4 | F15: =G15+H15/60+I15/3600-E15/3600 -> 144 | G15: =TRUNC(J15,0) -> 144 | H15: =TRUNC((J15-G15)*60,0) -> 20 | I15: =ROUND(((J15-G15)-H15/60)*3600,0) -> 14 | J15: =IF(K15<0,K15+360,K15) -> 144 | K15: =ATAN2(N15,Q15)/PI()*180 -> 144 | L15: =ROUND((SQRT(N15^2+Q15^2)),5) -> 46.551 | M15: =SQRT((T15-T14)^2+(U15-U14)^2) -> 46.551 | N15: =T15-T14-P15 -> -37.821 | O15: 46.55123 | P15: =ROUND(($T$82*$O15/$O$80),3) -> 0.001 | Q15: =U15-U14-R15 -> 27.140 | R15: =ROUND(($U$82*$O15/$O$80),3) -> 0.002 | S15: CM4 | T15: 45832.709 | U15: 210947.25
A16: =S16 -> CM5 | B16: =TRUNC(F16,0) -> 139 | C16: =TRUNC((F16-B16)*60,0) -> 18 | D16: =ROUND((F16-B16-C16/60)*3600,0) -> 6 | E16: =E15+E$84 -> 6 | F16: =G16+H16/60+I16/3600-E16/3600 -> 139 | G16: =TRUNC(J16,0) -> 139 | H16: =TRUNC((J16-G16)*60,0) -> 18 | I16: =ROUND(((J16-G16)-H16/60)*3600,0) -> 12 | J16: =IF(K16<0,K16+360,K16) -> 139 | K16: =ATAN2(N16,Q16)/PI()*180 -> 139 | L16: =ROUND((SQRT(N16^2+Q16^2)),5) -> 10.093 | M16: =SQRT((T16-T15)^2+(U16-U15)^2) -> 10.093 | N16: =T16-T15-P16 -> -7.652 | O16: 10.09139 | P16: =ROUND(($T$82*$O16/$O$80),3) -> 0.000 | Q16: =U16-U15-R16 -> 6.581 | R16: =ROUND(($U$82*$O16/$O$80),3) -> 0.000 | S16: CM5 | T16: 45825.057 | U16: 210953.83
A17: =S17 -> CM6 | B17: =TRUNC(F17,0) -> 229 | C17: =TRUNC((F17-B17)*60,0) -> 58 | D17: =ROUND((F17-B17-C17/60)*3600,0) -> 29 | E17: =E16+E$84 -> 7 | F17: =G17+H17/60+I17/3600-E17/3600 -> 230 | G17: =TRUNC(J17,0) -> 229 | H17: =TRUNC((J17-G17)*60,0) -> 58 | I17: =ROUND(((J17-G17)-H17/60)*3600,0) -> 36 | J17: =IF(K17<0,K17+360,K17) -> 230 | K17: =ATAN2(N17,Q17)/PI()*180 -> -130 | L17: =ROUND((SQRT(N17^2+Q17^2)),5) -> 14.761 | M17: =SQRT((T17-T16)^2+(U17-U16)^2) -> 14.761 | N17: =T17-T16-P17 -> -9.493 | O17: 14.76058 | P17: =ROUND(($T$82*$O17/$O$80),3) -> 0.000 | Q17: =U17-U16-R17 -> -11.304 | R17: =ROUND(($U$82*$O17/$O$80),3) -> 0.001 | S17: CM6 | T17: 45815.564 | U17: 210942.53
A18: =S18 -> CM7 | B18: =TRUNC(F18,0) -> 207 | C18: =TRUNC((F18-B18)*60,0) -> 16 | D18: =ROUND((F18-B18-C18/60)*3600,0) -> 40 | E18: =E17+E$84 -> 8 | F18: =G18+H18/60+I18/3600-E18/3600 -> 207 | G18: =TRUNC(J18,0) -> 207 | H18: =TRUNC((J18-G18)*60,0) -> 16 | I18: =ROUND(((J18-G18)-H18/60)*3600,0) -> 48 | J18: =IF(K18<0,K18+360,K18) -> 207 | K18: =ATAN2(N18,Q18)/PI()*180 -> -153 | L18: =ROUND((SQRT(N18^2+Q18^2)),5) -> 18.637 | M18: =SQRT((T18-T17)^2+(U18-U17)^2) -> 18.635 | N18: =T18-T17-P18 -> -16.564 | O18: 18.63549 | P18: =ROUND(($T$82*$O18/$O$80),3) -> 0.001 | Q18: =U18-U17-R18 -> -8.542 | R18: =ROUND(($U$82*$O18/$O$80),3) -> 0.001 | S18: CM7 | T18: 45799.001 | U18: 210933.99
A19: =S19 -> CL1 | B19: =TRUNC(F19,0) -> 223 | C19: =TRUNC((F19-B19)*60,0) -> 3 | D19: =ROUND((F19-B19-C19/60)*3600,0) -> 31 | E19: =E18+E$84 -> 9 | F19: =G19+H19/60+I19/3600-E19/3600 -> 223 | G19: =TRUNC(J19,0) -> 223 | H19: =TRUNC((J19-G19)*60,0) -> 3 | I19: =ROUND(((J19-G19)-H19/60)*3600,0) -> 40 | J19: =IF(K19<0,K19+360,K19) -> 223 | K19: =ATAN2(N19,Q19)/PI()*180 -> -137 | L19: =ROUND((SQRT(N19^2+Q19^2)),5) -> 18.120 | M19: =SQRT((T19-T18)^2+(U19-U18)^2) -> 18.119 | N19: =T19-T18-P19 -> -13.239 | O19: 18.12218 | P19: =ROUND(($T$82*$O19/$O$80),3) -> 0.001 | Q19: =U19-U18-R19 -> -12.372 | R19: =ROUND(($U$82*$O19/$O$80),3) -> 0.001 | S19: CL1 | T19: 45785.763 | U19: 210921.62
A20: =S20 -> CM8 | B20: =TRUNC(F20,0) -> 56 | C20: =TRUNC((F20-B20)*60,0) -> 50 | D20: =ROUND((F20-B20-C20/60)*3600,0) -> 51 | E20: =E19+E$84 -> 10 | F20: =G20+H20/60+I20/3600-E20/3600 -> 57 | G20: =TRUNC(J20,0) -> 56 | H20: =TRUNC((J20-G20)*60,0) -> 51 | I20: =ROUND(((J20-G20)-H20/60)*3600,0) -> 1 | J20: =IF(K20<0,K20+360,K20) -> 57 | K20: =ATAN2(N20,Q20)/PI()*180 -> 57 | L20: =ROUND((SQRT(N20^2+Q20^2)),5) -> 8.440 | M20: =SQRT((T20-T19)^2+(U20-U19)^2) -> 8.440 | N20: =T20-T19-P20 -> 4.615 | O20: 8.43598 | P20: =ROUND(($T$82*$O20/$O$80),3) -> 0.000 | Q20: =U20-U19-R20 -> 7.066 | R20: =ROUND(($U$82*$O20/$O$80),3) -> 0.000 | S20: CM8 | T20: 45790.378 | U20: 210928.68
A21: =S21 -> CM9 | B21: =TRUNC(F21,0) -> 308 | C21: =TRUNC((F21-B21)*60,0) -> 44 | D21: =ROUND((F21-B21-C21/60)*3600,0) -> 25 | E21: =E20+E$84 -> 11 | F21: =G21+H21/60+I21/3600-E21/3600 -> 309 | G21: =TRUNC(J21,0) -> 308 | H21: =TRUNC((J21-G21)*60,0) -> 44 | I21: =ROUND(((J21-G21)-H21/60)*3600,0) -> 36 | J21: =IF(K21<0,K21+360,K21) -> 309 | K21: =ATAN2(N21,Q21)/PI()*180 -> -51 | L21: =ROUND((SQRT(N21^2+Q21^2)),5) -> 23.533 | M21: =SQRT((T21-T20)^2+(U21-U20)^2) -> 23.533 | N21: =T21-T20-P21 -> 14.728 | O21: 23.53509 | P21: =ROUND(($T$82*$O21/$O$80),3) -> 0.001 | Q21: =U21-U20-R21 -> -18.355 | R21: =ROUND(($U$82*$O21/$O$80),3) -> 0.001 | S21: CM9 | T21: 45805.107 | U21: 210910.33
A22: =S22 -> CM10 | B22: =TRUNC(F22,0) -> 223 | C22: =TRUNC((F22-B22)*60,0) -> 37 | D22: =ROUND((F22-B22-C22/60)*3600,0) -> 32 | E22: =E21+E$84 -> 12 | F22: =G22+H22/60+I22/3600-E22/3600 -> 224 | G22: =TRUNC(J22,0) -> 223 | H22: =TRUNC((J22-G22)*60,0) -> 37 | I22: =ROUND(((J22-G22)-H22/60)*3600,0) -> 44 | J22: =IF(K22<0,K22+360,K22) -> 224 | K22: =ATAN2(N22,Q22)/PI()*180 -> -136 | L22: =ROUND((SQRT(N22^2+Q22^2)),5) -> 15.218 | M22: =SQRT((T22-T21)^2+(U22-U21)^2) -> 15.217 | N22: =T22-T21-P22 -> -11.015 | O22: 15.222 | P22: =ROUND(($T$82*$O22/$O$80),3) -> 0.000 | Q22: =U22-U21-R22 -> -10.500 | R22: =ROUND(($U$82*$O22/$O$80),3) -> 0.001 | S22: CM10 | T22: 45794.092 | U22: 210899.83
A23: =S23 -> CM11 | B23: =TRUNC(F23,0) -> 245 | C23: =TRUNC((F23-B23)*60,0) -> 38 | D23: =ROUND((F23-B23-C23/60)*3600,0) -> 60 | E23: =E22+E$84 -> 13 | F23: =G23+H23/60+I23/3600-E23/3600 -> 246 | G23: =TRUNC(J23,0) -> 245 | H23: =TRUNC((J23-G23)*60,0) -> 39 | I23: =ROUND(((J23-G23)-H23/60)*3600,0) -> 13 | J23: =IF(K23<0,K23+360,K23) -> 246 | K23: =ATAN2(N23,Q23)/PI()*180 -> -114 | L23: =ROUND((SQRT(N23^2+Q23^2)),5) -> 13.909 | M23: =SQRT((T23-T22)^2+(U23-U22)^2) -> 13.908 | N23: =T23-T22-P23 -> -5.734 | O23: 13.91067 | P23: =ROUND(($T$82*$O23/$O$80),3) -> 0.000 | Q23: =U23-U22-R23 -> -12.672 | R23: =ROUND(($U$82*$O23/$O$80),3) -> 0.001 | S23: CM11 | T23: 45788.358 | U23: 210887.16
A24: =S24 -> CM12 | B24: =TRUNC(F24,0) -> 247 | C24: =TRUNC((F24-B24)*60,0) -> 48 | D24: =ROUND((F24-B24-C24/60)*3600,0) -> 56 | E24: =E23+E$84 -> 14 | F24: =G24+H24/60+I24/3600-E24/3600 -> 248 | G24: =TRUNC(J24,0) -> 247 | H24: =TRUNC((J24-G24)*60,0) -> 49 | I24: =ROUND(((J24-G24)-H24/60)*3600,0) -> 10 | J24: =IF(K24<0,K24+360,K24) -> 248 | K24: =ATAN2(N24,Q24)/PI()*180 -> -112 | L24: =ROUND((SQRT(N24^2+Q24^2)),5) -> 37.340 | M24: =SQRT((T24-T23)^2+(U24-U23)^2) -> 37.338 | N24: =T24-T23-P24 -> -14.097 | O24: 37.34155 | P24: =ROUND(($T$82*$O24/$O$80),3) -> 0.001 | Q24: =U24-U23-R24 -> -34.577 | R24: =ROUND(($U$82*$O24/$O$80),3) -> 0.002 | S24: CM12 | T24: 45774.262 | U24: 210852.58
... A78: =S78 -> CM65 | B78: =TRUNC(F78,0) -> 150 | C78: =TRUNC((F78-B78)*60,0) -> 14 | D78: =ROUND((F78-B78-C78/60)*3600,0) -> 2 | E78: =E77+E$84 -> 74 | F78: =G78+H78/60+I78/3600-E78/3600 -> 150 | G78: =TRUNC(J78,0) -> 150 | H78: =TRUNC((J78-G78)*60,0) -> 15 | I78: =ROUND(((J78-G78)-H78/60)*3600,0) -> 16 | J78: =IF(K78<0,K78+360,K78) -> 150 | K78: =ATAN2(N78,Q78)/PI()*180 -> 150 | L78: =ROUND((SQRT(N78^2+Q78^2)),5) -> 56.826 | M78: =SQRT((T78-T77)^2+(U78-U77)^2) -> 56.825 | N78: =T78-T77-P78 -> -49.338 | O78: 56.8254 | P78: =ROUND(($T$82*$O78/$O$80),3) -> 0.002 | Q78: =U78-U77-R78 -> 28.194 | R78: =ROUND(($U$82*$O78/$O$80),3) -> 0.002 | S78: CM65 | T78: 45946.528 | U78: 210919.64
A79: =DTM!A7 -> cm2 | B79: =TRUNC(F79,0) -> 315 | C79: =TRUNC((F79-B79)*60,0) -> 4 | D79: =ROUND((F79-B79-C79/60)*3600,0) -> 33 | E79: =E78+E$84 -> 75 | F79: =G79+H79/60+I79/3600-E79/3600 -> 315 | G79: =TRUNC(J79,0) -> 315 | H79: =TRUNC((J79-G79)*60,0) -> 5 | I79: =ROUND(((J79-G79)-H79/60)*3600,0) -> 48 | J79: =IF(K79<0,K79+360,K79) -> 315 | K79: =ATAN2(N79,Q79)/PI()*180 -> -45 | L79: =ROUND((SQRT(N79^2+Q79^2)),5) -> 305.596 | M79: =SQRT((T79-T78)^2+(U79-U78)^2) -> 305.593 | N79: =T79-T78-P79 -> 216.453 | O79: 305.59362 | P79: =ROUND(($T$82*$O79/$O$80),3) -> 0.009 | Q79: =U79-U78-R79 -> -215.724 | R79: =ROUND(($U$82*$O79/$O$80),3) -> 0.013 | S79: =DTM!A7 -> cm2 | T79: =DTM!B7 -> 46162.990 | U79: =DTM!C7 -> 210703.930 | V79: =DTM!D7 -> I/s No.
A80: =DTM!A20 -> DD/6126 | B80: =TRUNC(F80,0) -> 99 | C80: =TRUNC((F80-B80)*60,0) -> 44 | D80: =ROUND((F80-B80-C80/60)*3600,0) -> 31 | E80: 74 | F80: =G80+H80/60+I80/3600-E80/3600 -> 100 | G80: =DTM!H21 -> 99 | H80: =DTM!I21 -> 45 | I80: =DTM!J21 -> 45 | L80: =SUM(L12:L79) -> 2834.441 | M80: =SUM(M12:M79) -> 2834.441 | N80: =SUM(N12:N79) -> 64.539 | O80: =SUM(O12:O79) -> 2834.454 | P80: =SUM(P12:P79) -> 0.081 | Q80: =SUM(Q12:Q79) -> -40.665 | R80: =SUM(R12:R79) -> 0.125 | S80: =A80 -> DD/6126 | T80: =T79-T11 -> 64.620 | U80: =U79-U11 -> -40.540 | V80: =DTM!D8 -> I/s No.
A81: =DTM!A23 -> cm1 | B81: =TRUNC(F81,0) -> 60 | C81: =TRUNC((F81-B81)*60,0) -> 16 | D81: =ROUND((F81-B81-C81/60)*3600,0) -> 26 | E81: 78 | F81: =G81+H81/60+I81/3600-E81/3600 -> 60 | G81: =DTM!H24 -> 60 | H81: =DTM!I24 -> 17 | I81: =DTM!J24 -> 44 | S81: =A81 -> cm1 | T81: =N80 -> 64.539 | U81: =Q80 -> -40.665 | V81: =DTM!D9 -> I/s No.
E82: =AVERAGE(E80:E81) -> 76 | T82: =SQRT((Q84^2)/2-(Q84^2)/5) -> 0.082 | U82: =SQRT(Q84^2-T82^2) -> 0.125
A83: Angular misclsure is
A84: 76" in 67 setups or | E84: =E82/COUNTA(A11:A79) -> 1.1 | G84: " per setup | L84: Linear misclosure is = | Q84: =ROUND((M80/T84),3) -> 0.149 | R84: m | S84: or 1 in | T84: 18994.606

Sheet AREA
C2: AREA COMPUTATION
B5: PLOT
B6: POINT | C6: N/m | D6: E/m | G6: DIST
B7: =TRVS!S11 -> DD/6124 | C7: =TRVS!T11 -> 46098.370 | D7: =TRVS!U11 -> 210744.470
B8: =TRVS!S12 -> CM1 | C8: =TRVS!T12 -> 45895.954 | D8: =TRVS!U12 -> 210949.513 | E8: =D7*C8 -> 9672318501 | F8: =C7*D8 -> 9724428702 | G8: =SQRT(((C8-C7)^2)+((D8-D7)^2)) -> 288.12
B9: =TRVS!S13 -> CM2 | C9: =TRVS!T13 -> 45877.618 | D9: =TRVS!U13 -> 210925.205 | E9: =D8*C9 -> 9677861175 | F9: =C8*D9 -> 9680613506 | G9: =SQRT(((C9-C8)^2)+((D9-D8)^2)) -> 30.45
B10: =TRVS!S14 -> CM3 | C10: =TRVS!T14 -> 45870.529 | D10: =TRVS!U14 -> 210920.108 | E10: =D9*C10 -> 9675250733 | F10: =C9*D10 -> 9676512143 | G10: =SQRT(((C10-C9)^2)+((D10-D9)^2)) -> 8.73
B11: =TRVS!S15 -> CM4 | C11: =TRVS!T15 -> 45832.709 | D11: =TRVS!U15 -> 210947.250 | E11: =D10*C11 -> 9667039932 | F11: =C10*D11 -> 9676261949 | G11: =SQRT(((C11-C10)^2)+((D11-D10)^2)) -> 46.55
B12: =TRVS!S16 -> CM5 | C12: =TRVS!T16 -> 45825.057 | D12: =TRVS!U16 -> 210953.831 | E12: =D11*C12 -> 9666669755 | F12: =C11*D12 -> 9668585549 | G12: =SQRT(((C12-C11)^2)+((D12-D11)^2)) -> 10.09
B13: =TRVS!S17 -> CM6 | C13: =TRVS!T17 -> 45815.564 | D13: =TRVS!U17 -> 210942.528 | E13: =D12*C13 -> 9664968745 | F13: =C12*D13 -> 9666453369 | G13: =SQRT(((C13-C12)^2)+((D13-D12)^2)) -> 14.76
B14: =TRVS!S18 -> CM7 | C14: =TRVS!T18 -> 45799.001 | D14: =TRVS!U18 -> 210933.987 | E14: =D13*C14 -> 9660957051 | F14: =C13*D14 -> 9664059581 | G14: =SQRT(((C14-C13)^2)+((D14-D13)^2)) -> 18.64
B15: =TRVS!S19 -> CL1 | C15: =TRVS!T19 -> 45785.763 | D15: =TRVS!U19 -> 210921.616 | E15: =D14*C15 -> 9657773537 | F15: =C14*D15 -> 9659999302 | G15: =SQRT(((C15-C14)^2)+((D15-D14)^2)) -> 18.12
B16: =TRVS!S20 -> CM8 | C16: =TRVS!T20 -> 45790.378 | D16: =TRVS!U20 -> 210928.682 | E16: =D15*C16 -> 9658180525 | F16: =C15*D16 -> 9657530644 | G16: =SQRT(((C16-C15)^2)+((D16-D15)^2)) -> 8.44
B17: =TRVS!S21 -> CM9 | C17: =TRVS!T21 -> 45805.107 | D17: =TRVS!U21 -> 210910.328 | E17: =D16*C17 -> 9661610848 | F17: =C16*D17 -> 9657663643 | G17: =SQRT(((C17-C16)^2)+((D17-D16)^2)) -> 23.53
B18: =TRVS!S22 -> CM10 | C18: =TRVS!T22 -> 45794.092 | D18: =TRVS!U22 -> 210899.829 | E18: =D17*C18 -> 9658446964 | F18: =C17*D18 -> 9660289234 | G18: =SQRT(((C18-C17)^2)+((D18-D17)^2)) -> 15.22
B19: =TRVS!S23 -> CM11 | C19: =TRVS!T23 -> 45788.358 | D19: =TRVS!U23 -> 210887.158 | E19: =D18*C19 -> 9656756872 | F19: =C18*D19 -> 9657385915 | G19: =SQRT(((C19-C18)^2)+((D19-D18)^2)) -> 13.91
... B21: =TRVS!S25 -> CM13 | C21: =TRVS!T25 -> 45751.134 | D21: =TRVS!U25 -> 210806.435 | E21: =D20*C21 -> 9646744779 | F21: =C20*D21 -> 9649508987 | G21: =SQRT(((C21-C20)^2)+((D21-D20)^2)) -> 51.62
B22: =TRVS!S57 -> CM44 | C22: =TRVS!T57 -> 46109.742 | D22: =TRVS!U57 -> 210456.958 | E22: =D21*C22 -> 9720230330 | F22: =C21*D22 -> 9628644487 | G22: =SQRT(((C22-C21)^2)+((D22-D21)^2)) -> 500.73
B23: =TRVS!S58 -> CM45 | C23: =TRVS!T58 -> 46117.554 | D23: =TRVS!U58 -> 210446.169 | E23: =D22*C23 -> 9705760125 | F23: =C22*D23 -> 9703618557 | G23: =SQRT(((C23-C22)^2)+((D23-D22)^2)) -> 13.32
B24: =TRVS!S59 -> CM46 | C24: =TRVS!T59 -> 46125.323 | D24: =TRVS!U59 -> 210437.830 | E24: =D23*C24 -> 9706897519 | F24: =C23*D24 -> 9704877989 | G24: =SQRT(((C24-C23)^2)+((D24-D23)^2)) -> 11.40
B25: =TRVS!S60 -> CM47 | C25: =TRVS!T60 -> 46133.871 | D25: =TRVS!U60 -> 210445.914 | E25: =D24*C25 -> 9708311703 | F25: =C24*D25 -> 9706885757 | G25: =SQRT(((C25-C24)^2)+((D25-D24)^2)) -> 11.77
B26: =TRVS!S61 -> CM48 | C26: =TRVS!T61 -> 46160.376 | D26: =TRVS!U61 -> 210476.087 | E26: =D25*C26 -> 9714262518 | F26: =C25*D26 -> 9710076646 | G26: =SQRT(((C26-C25)^2)+((D26-D25)^2)) -> 40.16
B27: =TRVS!S62 -> CM49 | C27: =TRVS!T62 -> 46152.216 | D27: =TRVS!U62 -> 210479.744 | E27: =D26*C27 -> 9713937830 | F27: =C26*D27 -> 9715824123 | G27: =SQRT(((C27-C26)^2)+((D27-D26)^2)) -> 8.94
B28: =TRVS!S63 -> CM50 | C28: =TRVS!T63 -> 46135.839 | D28: =TRVS!U63 -> 210492.333 | E28: =D27*C28 -> 9710659582 | F28: =C27*D28 -> 9714687619 | G28: =SQRT(((C28-C27)^2)+((D28-D27)^2)) -> 20.66
B29: =TRVS!S64 -> CM51 | C29: =TRVS!T64 -> 46100.916 | D29: =TRVS!U64 -> 210519.376 | E29: =D28*C29 -> 9703889362 | F29: =C28*D29 -> 9712488038 | G29: =SQRT(((C29-C28)^2)+((D29-D28)^2)) -> 44.17
B30: =TRVS!S65 -> CM52 | C30: =TRVS!T65 -> 46077.344 | D30: =TRVS!U65 -> 210537.256 | E30: =D29*C30 -> 9700173707 | F30: =C29*D30 -> 9705960354 | G30: =SQRT(((C30-C29)^2)+((D30-D29)^2)) -> 29.59
B31: =TRVS!S66 -> CM53 | C31: =TRVS!T66 -> 46080.710 | D31: =TRVS!U66 -> 210541.656 | E31: =D30*C31 -> 9701706238 | F31: =C30*D31 -> 9701200310 | G31: =SQRT(((C31-C30)^2)+((D31-D30)^2)) -> 5.54
B32: =TRVS!S67 -> CM54 | C32: =TRVS!T67 -> 46057.810 | D32: =TRVS!U67 -> 210565.320 | E32: =D31*C32 -> 9697087589 | F32: =C31*D32 -> 9702999447 | G32: =SQRT(((C32-C31)^2)+((D32-D31)^2)) -> 32.93
B33: =TRVS!#REF! -> #ERROR! | C33: =TRVS!#REF! -> #ERROR! | D33: =TRVS!#REF! -> #ERROR! | E33: =D32*C33 -> #ERROR! | F33: =C32*D33 -> #ERROR! | G33: =SQRT(((C33-C32)^2)+((D33-D32)^2)) -> #ERROR!
B34: =TRVS!S68 -> CM55 | C34: =TRVS!T68 -> 46042.247 | D34: =TRVS!U68 -> 210565.786 | E34: =D33*C34 -> #ERROR! | F34: =C33*D34 -> #ERROR! | G34: =SQRT(((C34-C33)^2)+((D34-D33)^2)) -> #ERROR!
B35: =TRVS!S69 -> CM56 | C35: =TRVS!T69 -> 45986.987 | D35: =TRVS!U69 -> 210528.326 | E35: =D34*C35 -> 9683286063 | F35: =C34*D35 -> 9693197186 | G35: =SQRT(((C35-C34)^2)+((D35-D34)^2)) -> 66.76
B36: =TRVS!S70 -> CM57 | C36: =TRVS!T70 -> 45966.170 | D36: =TRVS!U70 -> 210555.920 | E36: =D35*C36 -> 9677180823 | F36: =C35*D36 -> 9682832356 | G36: =SQRT(((C36-C35)^2)+((D36-D35)^2)) -> 34.57
B37: =TRVS!S71 -> CM58 | C37: =TRVS!T71 -> 45953.321 | D37: =TRVS!U71 -> 210580.352 | E37: =D36*C37 -> 9675743780 | F37: =C36*D37 -> 9679572259 | G37: =SQRT(((C37-C36)^2)+((D37-D36)^2)) -> 27.60
B38: =TRVS!S72 -> CM59 | C38: =TRVS!T72 -> 46007.415 | D38: =TRVS!U72 -> 210639.457 | E38: =D37*C38 -> 9688257645 | F38: =C37*D38 -> 9679582583 | G38: =SQRT(((C38-C37)^2)+((D38-D37)^2)) -> 80.12
B39: =TRVS!S73 -> CM60 | C39: =TRVS!T73 -> 46084.884 | D39: =TRVS!U73 -> 210729.415 | E39: =D38*C39 -> 9707294942 | F39: =C38*D39 -> 9695115649 | G39: =SQRT(((C39-C38)^2)+((D39-D38)^2)) -> 118.72
B40: =TRVS!S74 -> CM61 | C40: =TRVS!T74 -> 46123.233 | D40: =TRVS!U74 -> 210778.556 | E40: =D39*C40 -> 9719521908 | F40: =C39*D40 -> 9713705303 | G40: =SQRT(((C40-C39)^2)+((D40-D39)^2)) -> 62.33
B41: =TRVS!S75 -> CM62 | C41: =TRVS!T75 -> 46145.107 | D41: =TRVS!U75 -> 210812.512 | E41: =D40*C41 -> 9726399020 | F41: =C40*D41 -> 9723354610 | G41: =SQRT(((C41-C40)^2)+((D41-D40)^2)) -> 40.39
B42: =TRVS!#REF! -> #ERROR! | C42: =TRVS!#REF! -> #ERROR! | D42: =TRVS!#REF! -> #ERROR! | E42: =D41*C42 -> #ERROR! | F42: =C41*D42 -> #ERROR! | G42: =SQRT(((C42-C41)^2)+((D42-D41)^2)) -> #ERROR!
B43: =TRVS!#REF! -> #ERROR! | C43: =TRVS!#REF! -> #ERROR! | D43: =TRVS!#REF! -> #ERROR! | E43: =D42*C43 -> #ERROR! | F43: =C42*D43 -> #ERROR! | G43: =SQRT(((C43-C42)^2)+((D43-D42)^2)) -> #ERROR!
B44: =TRVS!#REF! -> #ERROR! | C44: =TRVS!#REF! -> #ERROR! | D44: =TRVS!#REF! -> #ERROR! | E44: =D43*C44 -> #ERROR! | F44: =C43*D44 -> #ERROR! | G44: =SQRT(((C44-C43)^2)+((D44-D43)^2)) -> #ERROR!
...
